<?xml version="1.0"?>
<robot name="my_robot" xmlns:xacro="http://www.ros.org/wiki/xacro">
    <material name="white">
        <color rgba="1 1 1 1" />
    </material>

    <material name="orange">
        <color rgba="1 0.3 0.1 1" />
    </material>

    <material name="blue">
        <color rgba="0.2 0.2 1 1" />
    </material>

    <material name="black">
        <color rgba="0 0 0 1" />
    </material>


    

    <link name="base_link">
        <inertial>
            <mass value="1.0" />
            <origin xyz="0.15 0 0.075" rpy="0 0 0" />
            <inertia ixx="0.2" ixy="0" ixz="0" iyy="0.2" iyz="0" izz="0.2" />
        </inertial>
        <visual>
            <origin xyz="0.15 0 0.075" rpy="0 0 0" />
            <geometry>
                <box size="0.3 0.3 0.15" />
            </geometry>
            <material name="white" />
        </visual>
        <collision>
            <origin xyz="0.15 0 0.075" rpy="0 0 0" />
            <geometry>
                <box size="0.3 0.3 0.15" />
            </geometry>
        </collision>
    </link>
    <gazebo reference="base_link">
        <material>Gazebo/White</material>
    </gazebo>

    <!-- LEFT WHEEL -->
    <joint name="left_wheel_joint" type="continuous">
        <parent link="base_link" />
        <child link="left_wheel" />
        <origin xyz="0.1 0.175 0" rpy="-1.57 0 0" />
        <axis xyz="0 0 1" />
    </joint>

    <link name="left_wheel">
        <inertial>
            <mass value="0.1" />
            <origin xyz="0 0 0" />
            <inertia ixx="0.002" ixy="0" ixz="0" iyy="0.002" iyz="0" izz="0.002" />
        </inertial>
        <visual>
            <geometry>
                <cylinder length="0.04" radius="0.05" />
            </geometry>
            <material name="blue" />
        </visual>
        <collision>
            <origin xyz="0 0 0" rpy="0 0 0" />
            <geometry>
                <cylinder length="0.04" radius="0.05" />
            </geometry>
        </collision>
    </link>
    <gazebo reference="left_wheel">
        <material>Gazebo/Black</material>

    </gazebo>

    <!-- RIGHT WHEEL -->
    <joint name="right_wheel_joint" type="continuous">
        <parent link="base_link" />
        <child link="right_wheel" />
        <origin xyz="0.1 -0.175 0" rpy="1.57 0 0" />
        <axis xyz="0 0 -1" />
    </joint>

    <link name="right_wheel">
        <inertial>
            <mass value="0.1" />
            <origin xyz="0 0 0" />
            <inertia ixx="0.002" ixy="0" ixz="0" iyy="0.002" iyz="0" izz="0.002" />
        </inertial>
        <visual>
            <geometry>
                <cylinder length="0.04" radius="0.05" />
            </geometry>
            <material name="blue" />
        </visual>
        <collision>
            <origin xyz="0 0 0" rpy="0 0 0" />
            <geometry>
                <cylinder length="0.04" radius="0.05" />
            </geometry>
        </collision>
    </link>
    <gazebo reference="right_wheel">
        <material>Gazebo/Black</material>

    </gazebo>

    <!-- CASTER WHEEL -->
    <joint name="caster_wheel_joint" type="fixed">
        <parent link="base_link" />
        <child link="caster_wheel" />
        <origin xyz="0.24 0 0" rpy="0 0 0" />
    </joint>

    <link name="caster_wheel">
        <visual>
            <geometry>
                <sphere radius="0.05" />
            </geometry>
            <material name="black" />
        </visual>
        <collision>
            <geometry>
                <sphere radius="0.05" />
            </geometry>
        </collision>
        <inertial>
            <mass value="0.2" />
            <origin xyz="0 0 0" />
            <inertia ixx="0.0002" ixy="0" ixz="0" iyy="0.0002" iyz="0" izz="0.0002" />
        </inertial>
    </link>

    <gazebo reference="caster_wheel">
        <material>Gazebo/Red</material>
        <mu1 value="0.001" />
        <mu2 value="0.001" />
    </gazebo>

    <joint name="imu_link_joint" type="fixed">
        <parent link="base_link" />
        <child link="imu_link" />
        <origin xyz="0.25 0 0.10" rpy="0 0 0" />
    </joint>
  <gazebo reference="imu_link">
        <material>Gazebo/Orange</material>
        <mu1 value="0.001" />
        <mu2 value="0.001" />
    </gazebo>
    <link name="imu_link">
        <inertial>
            <mass value="0.001"/>
            <origin xyz="0 0 0" rpy="0 0 0"/>
            <inertia ixx="0.000001" ixy="0" ixz="0" iyy="0.000001" iyz="0" izz="0.000001"/>
        </inertial>
        <visual>
            <geometry>
            <sphere radius="0.005"/>
            </geometry>
            <material name="gray">
            <color rgba="0.5 0.5 0.5 1.0"/>
            </material>
        </visual>
        <imu name="imu_sensor">
            <origin xyz="0 0 0" rpy="0 0 0"/>
            <acceleration>
            <noise>
                <covariance>0.04 0 0 0 0.04 0 0 0 0.04</covariance>
            </noise>
            </acceleration>
            <angular_velocity>
            <noise>
                <covariance>0.0025 0 0 0 0.0025 0 0 0 0.0025</covariance>
            </noise>
            </angular_velocity>
            <magnetic_field>
            <noise>
                <covariance>0.02 0 0 0 0.02 0 0 0 0.02</covariance>
            </noise>
            </magnetic_field>
        </imu>
    </link>

    <!-- LIDAR -->
    <joint name="lidar_joint" type="fixed">
        <parent link="base_link" />
        <child link="lidar" />
        <origin xyz="0.15 0 0.16" rpy="0 0 0" />
    </joint>

    <link name="lidar">
        <inertial>
            <mass value="0.1" />
            <origin xyz="0 0 0" />
            <inertia ixx="0.002" ixy="0" ixz="0" iyy="0.002" iyz="0" izz="0.002" />
        </inertial>
        <visual>
            <geometry>
                <cylinder length="0.04" radius="0.05" />
            </geometry>
            <material name="green" />
        </visual>
        <collision>
            <origin xyz="0 0 0" rpy="0 0 0" />
            <geometry>
                <cylinder length="0.04" radius="0.05" />
            </geometry>
        </collision>
    </link>

    <gazebo reference="lidar">
        <material>Gazebo/Yellow</material>

    </gazebo>
    <!-- CAMERA -->
    <joint name="camera_joint" type="fixed">
        <parent link="base_link" />
        <child link="camera" />
        <origin xyz="0.3 0 0.08" rpy="0 0 0" />
    </joint>

    <link name="camera">
        <inertial>
            <mass value="0.1" />
            <origin xyz="0 0 0" />
            <inertia ixx="0.002" ixy="0" ixz="0" iyy="0.002" iyz="0" izz="0.002" />
        </inertial>
        <visual>
            <geometry>
                <box size="0.02 0.05 0.03" />
            </geometry>
            <material name="yellow" />
        </visual>
        <collision>
            <origin xyz="0 0 0" rpy="0 0 0" />
            <geometry>
                <box size="0.02 0.03 0.03" />
            </geometry>
        </collision>
    </link>

    <gazebo reference="camera">
        <material>Gazebo/Blue</material>

    </gazebo>

    <gazebo reference="imu_link">
    <sensor name="imu_sensor" type="imu">
      <plugin filename="libgazebo_ros_imu_sensor.so" name="imu_plugin">
        <ros>
          <namespace>/demo</namespace>
          <remapping>~/out:=imu</remapping>
        </ros>
        <initial_orientation_as_reference>false</initial_orientation_as_reference>
      </plugin>
      <always_on>true</always_on>
      <update_rate>100</update_rate>
      <visualize>true</visualize>
     <imu>
     	<angular_velocity>
     	  <x>
     	    <noise type="gaussian">
              <mean>0.0</mean>
              <stddev>2e-4</stddev>
              <bias_mean>0.0000075</bias_mean>
              <bias_stddev>0.0000008</bias_stddev>
            </noise>
          </x>
          <y>
            <noise type="gaussian">
              <mean>0.0</mean>
              <stddev>2e-4</stddev>
              <bias_mean>0.0000075</bias_mean>
              <bias_stddev>0.0000008</bias_stddev>
            </noise>
          </y>
          <z>
            <noise type="gaussian">
              <mean>0.0</mean>
              <stddev>2e-4</stddev>
              <bias_mean>0.0000075</bias_mean>
              <bias_stddev>0.0000008</bias_stddev>
            </noise>
          </z>
        </angular_velocity>
        <linear_acceleration>
          <x>
            <noise type="gaussian">
              <mean>0.0</mean>
              <stddev>1.7e-2</stddev>
              <bias_mean>0.1</bias_mean>
              <bias_stddev>0.001</bias_stddev>
            </noise>
          </x>
          <y>
            <noise type="gaussian">
              <mean>0.0</mean>
              <stddev>1.7e-2</stddev>
              <bias_mean>0.1</bias_mean>
              <bias_stddev>0.001</bias_stddev>
            </noise>
          </y>
          <z>
            <noise type="gaussian">
              <mean>0.0</mean>
              <stddev>1.7e-2</stddev>
              <bias_mean>0.1</bias_mean>
              <bias_stddev>0.001</bias_stddev>
            </noise>
          </z>
        </linear_acceleration>
      </imu>
    </sensor>
  </gazebo>


<gazebo>
    <plugin name='diff_drive' filename='libgazebo_ros_diff_drive.so'>

      <!-- wheels -->
      <left_joint>left_wheel_joint</left_joint>
      <right_joint>right_wheel_joint</right_joint>

      <!-- kinematics -->
      <wheel_separation>1.66</wheel_separation>
      <wheel_diameter>0.8</wheel_diameter>

      <!-- limits -->	
      <max_wheel_torque>20</max_wheel_torque>
      <max_wheel_acceleration>1.0</max_wheel_acceleration>

      <!-- output -->
      <publish_odom>true</publish_odom>
      <publish_odom_tf>false</publish_odom_tf>
      <publish_wheel_tf>true</publish_wheel_tf>
            <command_topic>cmd_vel</command_topic>

      <odometry_frame>odom</odometry_frame>
      <robot_base_frame>base_link</robot_base_frame>
    </plugin>
  </gazebo>


  <gazebo reference="lidar">
    <sensor name="lidar" type="ray">
      <always_on>true</always_on>
      <visualize>true</visualize>
      <update_rate>5</update_rate>
      <ray>
        <scan>
          <horizontal>
            <samples>360</samples>
            <resolution>1.000000</resolution>
            <min_angle>0.000000</min_angle>
            <max_angle>6.280000</max_angle>
          </horizontal>
        </scan>
        <range>
          <min>0.120000</min>
          <max>3.5</max>
          <resolution>0.015000</resolution>
        </range>
        <noise>
          <type>gaussian</type>
          <mean>0.0</mean>
          <stddev>0.01</stddev>
        </noise>
      </ray>
      <plugin name="scan" filename="libgazebo_ros_ray_sensor.so">
        <ros>
          <remapping>~/out:=scan</remapping>
        </ros>
        <output_type>sensor_msgs/LaserScan</output_type>
        <frame_name>lidar</frame_name>
      </plugin>
    </sensor>
  </gazebo>

  <gazebo reference="camera_link">
    <sensor name="depth_camera" type="depth">
      <visualize>true</visualize>
      <update_rate>30.0</update_rate>
      <camera name="camera">
        <horizontal_fov>1.047198</horizontal_fov>
        <image>
          <width>640</width>
          <height>480</height>
          <format>R8G8B8</format>
        </image>
        <clip>
          <near>0.05</near>
          <far>3</far>
        </clip>
      </camera>
      <plugin name="depth_camera_controller" filename="libgazebo_ros_camera.so">
        <baseline>0.2</baseline>
        <alwaysOn>true</alwaysOn>
        <updateRate>0.0</updateRate>
        <frame_name>camera_depth_frame</frame_name>
        <pointCloudCutoff>0.5</pointCloudCutoff>
        <pointCloudCutoffMax>3.0</pointCloudCutoffMax>
        <distortionK1>0</distortionK1>
        <distortionK2>0</distortionK2>
        <distortionK3>0</distortionK3>
        <distortionT1>0</distortionT1>
        <distortionT2>0</distortionT2>
        <CxPrime>0</CxPrime>
        <Cx>0</Cx>
        <Cy>0</Cy>
        <focalLength>0</focalLength>
        <hackBaseline>0</hackBaseline>
      </plugin>
    </sensor>
  </gazebo>


</robot>
 